02-Jan-22 18:54:34 - INFO - Рассылка запущена...
02-Jan-22 18:54:34 - INFO - Лонгпул запущен...
02-Jan-22 18:54:34 - INFO - Бот запущен...
02-Jan-22 18:55:06 - INFO - Ответил: "Текущий уровень Q - 1" пользователю с id: 792302351
02-Jan-22 18:55:09 - INFO - Ответил: "Какой график вас интересует?" пользователю с id: 792302351
02-Jan-22 18:55:12 - INFO - Отправил фото пользователю с id: 792302351
02-Jan-22 18:55:16 - INFO - Ответил: "Список основных команд:
<b>"Подписаться"</b> - подписаться на какой-либо уровень Q
<b>"Отписаться"</b> - отписаться от какого-либо уровня Q
<b>"Стоп"</b> - отписаться от всех уровней, прекратить оповещение
<b>"Уровни"</b> - посмотреть соответствие уровней Q и земных широт
<b>"Графики"</b> - посмотреть изображения графиков с магнитометров
<b>"Баг-репорт"</b> - сообщить разработчику о проблемах с ботом" пользователю с id: 792302351
02-Jan-22 18:55:18 - INFO - Ответил: "Произошла ошибка: . Сообщите о ней в баг-репорте" пользователю с id: 792302351
02-Jan-22 18:55:19 - ERROR - Infinity polling exception: local variable 'connection' referenced before assignment
02-Jan-22 18:55:19 - ERROR - Exception traceback:
Traceback (most recent call last):
  File "C:\Users\astro\AppData\Roaming\Python\Python310\site-packages\telebot\__init__.py", line 617, in infinity_polling
    self.polling(none_stop=True, timeout=timeout, long_polling_timeout=long_polling_timeout,
  File "C:\Users\astro\AppData\Roaming\Python\Python310\site-packages\telebot\__init__.py", line 664, in polling
    self.__threaded_polling(non_stop, interval, timeout, long_polling_timeout, allowed_updates)
  File "C:\Users\astro\AppData\Roaming\Python\Python310\site-packages\telebot\__init__.py", line 726, in __threaded_polling
    raise e
  File "C:\Users\astro\AppData\Roaming\Python\Python310\site-packages\telebot\__init__.py", line 686, in __threaded_polling
    self.worker_pool.raise_exceptions()
  File "C:\Users\astro\AppData\Roaming\Python\Python310\site-packages\telebot\util.py", line 135, in raise_exceptions
    raise self.exception_info
  File "C:\Users\astro\AppData\Roaming\Python\Python310\site-packages\telebot\util.py", line 87, in run
    task(*args, **kwargs)
  File "d:\Документы\TEMP\tg_bot\longpool.py", line 55, in unsubscribe
    delete_from_db(message.from_user.id, False)
  File "d:\Документы\TEMP\tg_bot\functions\db_functions.py", line 59, in delete_from_db
    if connection:
UnboundLocalError: local variable 'connection' referenced before assignment

02-Jan-22 18:55:34 - INFO - Функция анализа запущена
02-Jan-22 18:56:01 - INFO - Функция анализа завершена
02-Jan-22 18:57:01 - INFO - Функция анализа запущена
02-Jan-22 18:57:26 - INFO - Функция анализа завершена
02-Jan-22 18:58:27 - INFO - Функция анализа запущена
02-Jan-22 18:58:51 - INFO - Функция анализа завершена
02-Jan-22 18:59:51 - INFO - Функция анализа запущена
02-Jan-22 19:00:15 - INFO - Функция анализа завершена
02-Jan-22 19:01:16 - INFO - Функция анализа запущена
02-Jan-22 19:01:32 - INFO - Функция анализа завершена
02-Jan-22 19:02:33 - INFO - Функция анализа запущена
02-Jan-22 19:02:50 - INFO - Функция анализа завершена
